<?xml version='1.0'?>
<sdf version='1.8'>
    <model name="x3_realsense">
        <pose>0 0 0.053302 0 0 0</pose>
        <link name='X3/base_link'>
        <pose frame=''>0 0 0 0 -0 0</pose>
        <inertial>
            <pose frame=''>0 0 0 0 -0 0</pose>
            <mass>1.5</mass>
            <inertia>
            <ixx>0.0347563</ixx>
            <ixy>0</ixy>
            <ixz>0</ixz>
            <iyy>0.07</iyy>
            <iyz>0</iyz>
            <izz>0.0977</izz>
            </inertia>
        </inertial>
        <collision name='X3/base_link_inertia_collision'>
            <pose frame=''>0 0 0 0 -0 0</pose>
            <geometry>
            <box>
                <size>0.47 0.47 0.11</size>
            </box>
            </geometry>
        </collision>
        <visual name='X3/base_link_inertia_visual'>
            <pose frame=''>0 0 0 0 -0 0</pose>
            <geometry>
            <mesh>
                <scale>1 1 1</scale>
                <uri>model://x3/meshes/x3.dae</uri>
            </mesh>
            </geometry>
        </visual>
        <sensor name="imu_sensor" type="imu">
            <always_on>1</always_on>
            <update_rate>250</update_rate>
            <visualize>true</visualize>
            <topic>imu</topic>
        </sensor>
        </link>
        <link name='X3/rotor_0'>
        <pose frame=''>0.13 -0.22 0.023 0 -0 0</pose>
        <inertial>
            <pose frame=''>0 0 0 0 -0 0</pose>
            <mass>0.005</mass>
            <inertia>
            <ixx>9.75e-07</ixx>
            <ixy>0</ixy>
            <ixz>0</ixz>
            <iyy>4.17041e-05</iyy>
            <iyz>0</iyz>
            <izz>4.26041e-05</izz>
            </inertia>
        </inertial>
        <collision name='X3/rotor_0_collision'>
            <pose frame=''>0 0 0 0 -0 0</pose>
            <geometry>
            <cylinder>
                <length>0.005</length>
                <radius>0.1</radius>
            </cylinder>
            </geometry>
            <surface>
            <contact>
                <ode/>
            </contact>
            <friction>
                <ode/>
            </friction>
            </surface>
        </collision>
        <visual name='X3/rotor_0_visual'>
            <pose frame=''>0 0 0 0 -0 0</pose>
            <geometry>
            <mesh>
                <scale>0.1 0.1 0.1</scale>
                <uri>model://x3/meshes/propeller_ccw.dae</uri>
            </mesh>
            </geometry>
            <material>
            <script>
                <name>Gazebo/Blue</name>
                <uri>file://media/materials/scripts/gazebo.material</uri>
            </script>
            </material>
        </visual>
        <gravity>1</gravity>
        <velocity_decay/>
        </link>
        <joint name='X3/rotor_0_joint' type='revolute'>
        <child>X3/rotor_0</child>
        <parent>X3/base_link</parent>
        <axis>
            <xyz>0 0 1</xyz>
            <limit>
            <lower>-1e+16</lower>
            <upper>1e+16</upper>
            </limit>
            <dynamics>
            <spring_reference>0</spring_reference>
            <spring_stiffness>0</spring_stiffness>
            </dynamics>
            <use_parent_model_frame>1</use_parent_model_frame>
        </axis>
        </joint>
        <link name='X3/rotor_1'>
        <pose frame=''>-0.13 0.2 0.023 0 -0 0</pose>
        <inertial>
            <pose frame=''>0 0 0 0 -0 0</pose>
            <mass>0.005</mass>
            <inertia>
            <ixx>9.75e-07</ixx>
            <ixy>0</ixy>
            <ixz>0</ixz>
            <iyy>4.17041e-05</iyy>
            <iyz>0</iyz>
            <izz>4.26041e-05</izz>
            </inertia>
        </inertial>
        <collision name='X3/rotor_1_collision'>
            <pose frame=''>0 0 0 0 -0 0</pose>
            <geometry>
            <cylinder>
                <length>0.005</length>
                <radius>0.1</radius>
            </cylinder>
            </geometry>
            <surface>
            <contact>
                <ode/>
            </contact>
            <friction>
                <ode/>
            </friction>
            </surface>
        </collision>
        <visual name='X3/rotor_1_visual'>
            <pose frame=''>0 0 0 0 -0 0</pose>
            <geometry>
            <mesh>
                <scale>0.1 0.1 0.1</scale>
                <uri>model://x3/meshes/propeller_ccw.dae</uri>
            </mesh>
            </geometry>
            <material>
            <script>
                <name>Gazebo/Red</name>
                <uri>file://media/materials/scripts/gazebo.material</uri>
            </script>
            </material>
        </visual>
        <gravity>1</gravity>
        <velocity_decay/>
        </link>
        <joint name='X3/rotor_1_joint' type='revolute'>
        <child>X3/rotor_1</child>
        <parent>X3/base_link</parent>
        <axis>
            <xyz>0 0 1</xyz>
            <limit>
            <lower>-1e+16</lower>
            <upper>1e+16</upper>
            </limit>
            <dynamics>
            <spring_reference>0</spring_reference>
            <spring_stiffness>0</spring_stiffness>
            </dynamics>
            <use_parent_model_frame>1</use_parent_model_frame>
        </axis>
        </joint>
        <link name='X3/rotor_2'>
        <pose frame=''>0.13 0.22 0.023 0 -0 0</pose>
        <inertial>
            <pose frame=''>0 0 0 0 -0 0</pose>
            <mass>0.005</mass>
            <inertia>
            <ixx>9.75e-07</ixx>
            <ixy>0</ixy>
            <ixz>0</ixz>
            <iyy>4.17041e-05</iyy>
            <iyz>0</iyz>
            <izz>4.26041e-05</izz>
            </inertia>
        </inertial>
        <collision name='X3/rotor_2_collision'>
            <pose frame=''>0 0 0 0 -0 0</pose>
            <geometry>
            <cylinder>
                <length>0.005</length>
                <radius>0.1</radius>
            </cylinder>
            </geometry>
            <surface>
            <contact>
                <ode/>
            </contact>
            <friction>
                <ode/>
            </friction>
            </surface>
        </collision>
        <visual name='X3/rotor_2_visual'>
            <pose frame=''>0 0 0 0 -0 0</pose>
            <geometry>
            <mesh>
                <scale>0.1 0.1 0.1</scale>
                <uri>model://x3/meshes/propeller_cw.dae</uri>
            </mesh>
            </geometry>
            <material>
            <script>
                <name>Gazebo/Blue</name>
                <uri>file://media/materials/scripts/gazebo.material</uri>
            </script>
            </material>
        </visual>
        <gravity>1</gravity>
        <velocity_decay/>
        </link>
        <joint name='X3/rotor_2_joint' type='revolute'>
        <child>X3/rotor_2</child>
        <parent>X3/base_link</parent>
        <axis>
            <xyz>0 0 1</xyz>
            <limit>
            <lower>-1e+16</lower>
            <upper>1e+16</upper>
            </limit>
            <dynamics>
            <spring_reference>0</spring_reference>
            <spring_stiffness>0</spring_stiffness>
            </dynamics>
            <use_parent_model_frame>1</use_parent_model_frame>
        </axis>
        </joint>
        <link name='X3/rotor_3'>
        <pose frame=''>-0.13 -0.2 0.023 0 -0 0</pose>
        <inertial>
            <pose frame=''>0 0 0 0 -0 0</pose>
            <mass>0.005</mass>
            <inertia>
            <ixx>9.75e-07</ixx>
            <ixy>0</ixy>
            <ixz>0</ixz>
            <iyy>4.17041e-05</iyy>
            <iyz>0</iyz>
            <izz>4.26041e-05</izz>
            </inertia>
        </inertial>
        <collision name='X3/rotor_3_collision'>
            <pose frame=''>0 0 0 0 -0 0</pose>
            <geometry>
            <cylinder>
                <length>0.005</length>
                <radius>0.1</radius>
            </cylinder>
            </geometry>
            <surface>
            <contact>
                <ode/>
            </contact>
            <friction>
                <ode/>
            </friction>
            </surface>
        </collision>
        <visual name='X3/rotor_3_visual'>
            <pose frame=''>0 0 0 0 -0 0</pose>
            <geometry>
            <mesh>
                <scale>0.1 0.1 0.1</scale>
                <uri>model://x3/meshes/propeller_cw.dae</uri>
            </mesh>
            </geometry>
            <material>
            <script>
                <name>Gazebo/Red</name>
                <uri>file://media/materials/scripts/gazebo.material</uri>
            </script>
            </material>
        </visual>
        <gravity>1</gravity>
        <velocity_decay/>
        </link>
        <joint name='X3/rotor_3_joint' type='revolute'>
        <child>X3/rotor_3</child>
        <parent>X3/base_link</parent>
        <axis>
            <xyz>0 0 1</xyz>
            <limit>
            <lower>-1e+16</lower>
            <upper>1e+16</upper>
            </limit>
            <dynamics>
            <spring_reference>0</spring_reference>
            <spring_stiffness>0</spring_stiffness>
            </dynamics>
            <use_parent_model_frame>1</use_parent_model_frame>
        </axis>
        </joint>
        <plugin
        filename="libgazebo_barometer_plugin.so"
        name="barometer_plugin::BarometerPlugin">
        <link_name>X3/base_link</link_name>
        </plugin>
        <plugin
        filename="libgazebo_magnetometer_plugin.so"
        name="magnetometer_plugin::MagnetometerPlugin">
        <link_name>X3/base_link</link_name>
        </plugin>
        <plugin
        filename="libgazebo_gps_plugin.so"
        name="gps_plugin::GpsPlugin">
        <link_name>X3/base_link</link_name>
        </plugin>

        <link name="realsense_d435">
            <pose>0.1 0.01 0 0 0 1.57</pose>
            <inertial>
                <!-- TODO: need to figure out how to provide more motor power in sim to use mass, falls out of sky rn -->
                <!-- <mass>0.0615752</mass> -->
                <mass>0.000001</mass>
                <inertia>
                <ixx>9.108e-05</ixx>
                <ixy>0</ixy>
                <ixz>0</ixz>
                <iyy>2.51e-06</iyy>
                <iyz>0</iyz>
                <izz>8.931e-05</izz>
                </inertia>
                <pose frame=''>0 0 0 0 -0 0</pose>
            </inertial>
            <collision name="collision">
                <geometry>
                <mesh>
                    <uri>model://RealSense_D435/meshes/realsense.dae</uri>
                </mesh>
                </geometry>
            </collision>
            <visual name= "visual">
                <geometry>
                <mesh>
                    <uri>model://RealSense_D435/meshes/realsense.dae</uri>
                    <submesh>
                    <name>RealSense</name>
                    <center>false</center>
                    </submesh>
                </mesh>
                </geometry>
                <material>
                <diffuse>1.0 1.0 1.0</diffuse>
                <specular>1.0 1.0 1.0</specular>
                <pbr>
                    <metal>
                    <albedo_map>model://RealSense_D435/materials/textures/RealSense_Albedo.png</albedo_map>
                    <normal_map>model://RealSense_D435/materials/textures/RealSense_Normal.png</normal_map>
                    <metalness_map>model://RealSense_D435/materials/textures/RealSense_Metalness.png</metalness_map>
                    <roughness_map>model://RealSense_D435/materials/textures/RealSense_Roughness.png</roughness_map>
                    </metal>
                </pbr>
                <!-- fallback to script if no PBR support-->
                <script>
                    <uri>model://RealSense_D435/materials/scripts/</uri>
                    <uri>model://RealSense_D435/materials/textures/</uri>
                    <name>UrbanTile/RealSense_Diffuse</name>
                </script>
                </material>
            </visual>
            <sensor name="realsense_d435" type="rgbd_camera">
                <pose>0 0 0 0 0 -1.57</pose>
                <update_rate>60</update_rate>
                <camera name="camera">
                <horizontal_fov>1.0472</horizontal_fov>
                <lens>
                    <intrinsics>
                    <!-- fx = fy = width / ( 2 * tan (hfov / 2 ) ) -->
                    <fx>554.25469</fx>
                    <fy>554.25469</fy>
                    <!-- cx = ( width + 1 ) / 2 -->
                    <cx>320.5</cx>
                    <!-- cy = ( height + 1 ) / 2 -->
                    <cy>240.5</cy>
                    <s>0</s>
                    </intrinsics>
                </lens>
                <distortion>
                    <k1>0.0</k1>
                    <k2>0.0</k2>
                    <k3>0.0</k3>
                    <p1>0.0</p1>
                    <p2>0.0</p2>
                    <center>0.5 0.5</center>
                </distortion>
                <image>
                    <width>640</width>
                    <height>480</height>
                    <format>R8G8B8</format>
                </image>
                <clip>
                    <near>0.01</near>
                    <far>300</far>
                </clip>
                <depth_camera>
                    <clip>
                    <near>0.1</near>
                    <far>10</far>
                    </clip>
                </depth_camera>
                <noise>
                    <type>gaussian</type>
                    <mean>0</mean>
                    <stddev>0.007</stddev>
                </noise>
                </camera>
            </sensor>
        </link>
        <joint name='X3/realsense_joint' type='fixed'>
            <child>realsense_d435</child>
            <parent>X3/base_link</parent>
        </joint>

    </model>
</sdf>